<mujoco>
  <option gravity="0 0 0"/>
  <worldbody>
    <body name="mass" pos="-1 0 0.5">
      <geom type="box" size="0.3 0.3 0.3" density="1" rgba="0.2 0.8 0.2 1"/>
      <joint name="mass_joint" type="slide" axis="1 0 0"/>
    </body>
    <body name="spring" pos="0 0 0.5">
      <geom type="capsule" fromto="0 0 0 -1 0 0" radius="0.05" rgba="0.8 0.8 0.2 1"/>
    </body>
    <body name="damper" pos="0 0 0.5">
      <geom type="cylinder" size="0.05 1" rgba="0.3 0.3 0.8 1"/>
    </body>
    <body name="surface" pos="-10 0 0">
      <geom type="plane" size="20 20 0.1" rgba="0.9 0.9 0.9 1" friction="0.1 0.1 0.1"/>
    </body>
  </worldbody>
</mujoco>
