<mujoco>
  <option gravity="0 0 -9.81"/>
  <worldbody>
    <body name="moving_obstacle" pos="5 0 0">
      <geom type="box" size="0.5 1.5 1.5" rgba="0.7 0.3 0.3 1"/>
      <joint name="slide_x" type="slide" axis="1 0 0" range="-2 2"/>
      <motor joint="slide_x" ctrlrange="-2 2" ctrllimited="true"/>
    </body>
    <body name="ground" pos="0 0 -0.1">
      <geom type="plane" size="30 30 0.1" rgba="0.8 0.8 0.8 1"/>
    </body>
    <body name="projectile" pos="-5 0 1">
      <geom type="sphere" size="0.2" density="1" rgba="0.2 0.8 0.2 1"/>
      <joint type="free"/>
    </body>
  </worldbody>
</mujoco>
