<mujoco>
  <option gravity="0 0 -9.81"/>
  <worldbody>
    <body name="ramp" pos="0 0 0">
      <geom type="plane" size="5 10 0.1" rgba="0.7 0.7 0.7 1" friction="0 0 0" quat="0.5 0.866 0 0"/>
    </body>
    <body name="surface" pos="-10 0 -10">
      <geom type="plane" size="30 30 0.1" rgba="0.85 0.85 0.85 1" friction="1 1 1"/>
    </body>
    <body name="pendulum" pos="-5 0 2.5">
      <geom type="capsule" fromto="0 0 0 0 0 -1.8" radius="0.04" rgba="0.2 0.9 0.9 1"/>
      <joint name="pendulum_joint" type="hinge" axis="0 1 0"/>
    </body>
    <body name="block" pos="5 0 1.5">
      <geom type="box" size="0.4 0.4 0.4" density="1" rgba="1 0.3 0.3 1" friction="0 0 0"/>
      <joint name="block_joint" type="free"/>
    </body>
  </worldbody>
</mujoco>
