<mujoco>
  <option gravity="0 0 -9.81"/>
  <worldbody>
    <body name="hinge" pos="0 0 0">
      <geom type="cylinder" size="0.1 0.05" rgba="0.5 0.5 0.5 1"/>
    </body>
    <body name="support" pos="0 0 1">
      <geom type="box" size="0.2 0.2 0.2" rgba="0.6 0.6 0.6 1"/>
    </body>
    <body name="surface" pos="-10 0 -0.1">
      <geom type="plane" size="30 30 0.1" rgba="0.7 0.7 0.7 1"/>
    </body>
    <body name="door" pos="1.2 0 1">
      <geom type="box" size="0.1 0.5 2" density="3" rgba="0.3 0.3 0.9 1"/>
      <joint name="door_joint" type="hinge" axis="0 0 1"/>
    </body>
  </worldbody>
</mujoco>
