<mujoco>
  <option gravity="0 0 -9.81"/>
  <worldbody>
    <body name="object" pos="0 0 1">
      <geom type="capsule" size="0.3 0.3" rgba="0.5 0.5 0.5 1"/>
      <joint name="initial_motion" type="slide" axis="1 0 0" />
    </body>
    <body name="fragment1" pos="-1 0 1">
      <geom type="box" size="0.3 0.3 0.3" density="1" rgba="0.1 0.8 0.1 1"/>
      <joint type="free"/>
    </body>
    <body name="fragment2" pos="1 0 1">
      <geom type="box" size="0.3 0.3 0.3" density="1" rgba="0.8 0.1 0.1 1"/>
      <joint type="free"/>
    </body>
  </worldbody>
</mujoco>
