<mujoco>
  <option gravity="0 0 -9.81"/>
  <worldbody>
    <body name="mass" pos="0 0 2">
      <geom type="sphere" size="0.2" density="1" rgba="0.8 0.2 0.2 1"/>
      <joint name="mass_joint" type="slide" axis="0 0 1"/>
    </body>
    <body name="spring" pos="0 0 3">
      <geom type="capsule" fromto="0 0 3 0 0 2" radius="0.05" rgba="0.8 0.8 0.2 1"/>
    </body>
    <body name="damper" pos="0.1 0 3">
      <geom type="cylinder" size="0.05 1" rgba="0.3 0.3 0.8 1"/>
    </body>
    <body name="ceiling" pos="0 0 3.1">
      <geom type="box" size="0.5 0.5 0.05" rgba="0.6 0.6 0.6 1"/>
    </body>
  </worldbody>
</mujoco>
