<mujoco>
  <option gravity="0 0 -9.81"/>
  <worldbody>
    <body name="support" pos="0 0 2">
      <geom type="sphere" size="0.2" rgba="0.6 0.6 0.6 1"/>
    </body>
    <body name="pendulum1_heavy" pos="-1 0 2">
      <geom type="capsule" fromto="0 0 0 0 0 -1" radius="0.05" density="5" rgba="0.8 0.2 0.2 1"/>
      <joint name="p1_joint" type="hinge" axis="0 1 0"/>
    </body>
    <body name="pendulum2_light" pos="-1 0 1">
      <geom type="capsule" fromto="0 0 0 0 0 -1" radius="0.05" density="0.5" rgba="0.2 0.2 0.8 1"/>
      <joint name="p2_joint" type="hinge" axis="0 1 0"/>
    </body>
  </worldbody>
</mujoco>
