<mujoco>
  <option gravity="0 0 -9.81"/>
  <worldbody>
    <!-- Elevator A -->
    <body name="elevator_A" pos="-3 0 0">
      <geom type="box" size="1.5 1.5 1" rgba="0.6 0.6 0.8 1"/>
      <joint name="elevator_A_joint" type="slide" axis="0 0 1"/>
    </body>
    <body name="block_A" pos="-3 0 1">
      <geom type="box" size="0.4 0.4 0.4" density="1" rgba="0 0 1 1"/>
    </body>
    <body name="scale_A" pos="-3 0 -0.5">
      <geom type="box" size="0.4 0.4 0.1" rgba="0.7 0.7 0.7 1"/>
    </body>

    <!-- Elevator B -->
    <body name="elevator_B" pos="3 0 0">
      <geom type="box" size="1.5 1.5 1" rgba="0.8 0.6 0.6 1"/>
      <joint name="elevator_B_joint" type="slide" axis="0 0 1"/>
    </body>
    <body name="block_B" pos="3 0 1">
      <geom type="box" size="0.4 0.4 0.4" density="1" rgba="1 0 0 1"/>
    </body>
    <body name="scale_B" pos="3 0 -0.5">
      <geom type="box" size="0.4 0.4 0.1" rgba="0.7 0.7 0.7 1"/>
    </body>

    <!-- Shaft -->
    <body name="shaft" pos="0 0 -5">
      <geom type="cylinder" size="1 10" rgba="0.3 0.3 0.3 1"/>
    </body>
  </worldbody>
</mujoco>
