<mujoco>
  <option gravity="0 0 -9.81"/>
  <worldbody>
    <!-- Underdamped system -->
    <body name="mass1" pos="-2 0 1">
      <geom type="box" size="0.3 0.3 0.3" density="1" rgba="0.2 0.8 0.2 1"/>
      <joint type="slide" axis="1 0 0"/>
    </body>
    <body name="spring1" pos="-1 0 1">
      <geom type="capsule" fromto="-1 0 1 -2 0 1" radius="0.05" rgba="0.8 0.8 0.2 1"/>
    </body>
    <body name="damper1" pos="-1 0 1">
      <geom type="cylinder" size="0.05 1" rgba="0.3 0.3 0.8 1"/>
    </body>

    <!-- Overdamped system -->
    <body name="mass2" pos="2 0 1">
      <geom type="box" size="0.3 0.3 0.3" density="1" rgba="0.2 0.2 0.8 1"/>
      <joint type="slide" axis="1 0 0"/>
    </body>
    <body name="spring2" pos="1 0 1">
      <geom type="capsule" fromto="1 0 1 2 0 1" radius="0.05" rgba="0.8 0.8 0.2 1"/>
    </body>
    <body name="damper2" pos="1 0 1">
      <geom type="cylinder" size="0.05 1" rgba="0.3 0.3 0.3 1"/>
    </body>
  </worldbody>
</mujoco>
