<mujoco>
  <option gravity="0 0 -9.81"/>
  <worldbody>
    <body name="support" pos="0 0 2">
      <geom type="sphere" size="0.2" rgba="0.5 0.5 0.5 1"/>
    </body>
    <body name="pendulum1_offset" pos="0.2 0 2">
      <geom type="capsule" fromto="0 0 0 0.2 0 -1" radius="0.05" rgba="0.9 0.3 0.3 1"/>
      <joint name="p1_offset_joint" type="hinge" axis="0 1 0"/>
    </body>
    <body name="pendulum2_offset" pos="0.4 0 1">
      <geom type="capsule" fromto="0 0 0 0.2 0 -1" radius="0.05" rgba="0.3 0.3 0.9 1"/>
      <joint name="p2_offset_joint" type="hinge" axis="0 1 0"/>
    </body>
  </worldbody>
</mujoco>
